[2024-02-03T05:06:42.306+0000] {taskinstance.py:1957} INFO - Dependencies all met for dep_context=non-requeueable deps ti=<TaskInstance: weather_api_dag.load_data_to_postgres scheduled__2024-02-03T04:00:00+00:00 [queued]>
[2024-02-03T05:06:42.312+0000] {taskinstance.py:1957} INFO - Dependencies all met for dep_context=requeueable deps ti=<TaskInstance: weather_api_dag.load_data_to_postgres scheduled__2024-02-03T04:00:00+00:00 [queued]>
[2024-02-03T05:06:42.312+0000] {taskinstance.py:2171} INFO - Starting attempt 3 of 3
[2024-02-03T05:06:42.327+0000] {taskinstance.py:2192} INFO - Executing <Task(PythonOperator): load_data_to_postgres> on 2024-02-03 04:00:00+00:00
[2024-02-03T05:06:42.332+0000] {standard_task_runner.py:60} INFO - Started process 11267 to run task
[2024-02-03T05:06:42.335+0000] {standard_task_runner.py:87} INFO - Running: ['***', 'tasks', 'run', 'weather_api_dag', 'load_data_to_postgres', 'scheduled__2024-02-03T04:00:00+00:00', '--job-id', '197', '--raw', '--subdir', 'DAGS_FOLDER/weather_api__dag.py', '--cfg-path', '/tmp/tmpbswalk42']
[2024-02-03T05:06:42.337+0000] {standard_task_runner.py:88} INFO - Job 197: Subtask load_data_to_postgres
[2024-02-03T05:06:42.378+0000] {task_command.py:423} INFO - Running <TaskInstance: weather_api_dag.load_data_to_postgres scheduled__2024-02-03T04:00:00+00:00 [running]> on host 324edfad8c3f
[2024-02-03T05:06:42.455+0000] {taskinstance.py:2481} INFO - Exporting env vars: AIRFLOW_CTX_DAG_OWNER='***' AIRFLOW_CTX_DAG_ID='weather_api_dag' AIRFLOW_CTX_TASK_ID='load_data_to_postgres' AIRFLOW_CTX_EXECUTION_DATE='2024-02-03T04:00:00+00:00' AIRFLOW_CTX_TRY_NUMBER='3' AIRFLOW_CTX_DAG_RUN_ID='scheduled__2024-02-03T04:00:00+00:00'
[2024-02-03T05:06:42.456+0000] {taskinstance.py:2699} ERROR - Task failed with exception
Traceback (most recent call last):
  File "/home/airflow/.local/lib/python3.8/site-packages/airflow/models/taskinstance.py", line 433, in _execute_task
    result = execute_callable(context=context, **execute_callable_kwargs)
  File "/home/airflow/.local/lib/python3.8/site-packages/airflow/operators/python.py", line 199, in execute
    return_value = self.execute_callable()
  File "/home/airflow/.local/lib/python3.8/site-packages/airflow/operators/python.py", line 216, in execute_callable
    return self.python_callable(*self.op_args, **self.op_kwargs)
  File "/opt/airflow/dags/weather_api__dag.py", line 40, in _load_data_to_postgres
    file_name  = ti.xcom_pull(task_id="get_weather_data", key="return_value")
  File "/home/airflow/.local/lib/python3.8/site-packages/airflow/utils/session.py", line 79, in wrapper
    return func(*args, session=session, **kwargs)
TypeError: xcom_pull() got an unexpected keyword argument 'task_id'
[2024-02-03T05:06:42.463+0000] {taskinstance.py:1138} INFO - Marking task as FAILED. dag_id=weather_api_dag, task_id=load_data_to_postgres, execution_date=20240203T040000, start_date=20240203T050642, end_date=20240203T050642
[2024-02-03T05:06:42.477+0000] {standard_task_runner.py:107} ERROR - Failed to execute job 197 for task load_data_to_postgres (xcom_pull() got an unexpected keyword argument 'task_id'; 11267)
[2024-02-03T05:06:42.507+0000] {local_task_job_runner.py:234} INFO - Task exited with return code 1
[2024-02-03T05:06:42.525+0000] {taskinstance.py:3281} INFO - 0 downstream tasks scheduled from follow-on schedule check
