[2024-02-03T05:00:07.297+0000] {taskinstance.py:1957} INFO - Dependencies all met for dep_context=non-requeueable deps ti=<TaskInstance: weather_api_dag.load_data_to_postgres scheduled__2024-02-03T04:00:00+00:00 [queued]>
[2024-02-03T05:00:07.304+0000] {taskinstance.py:1957} INFO - Dependencies all met for dep_context=requeueable deps ti=<TaskInstance: weather_api_dag.load_data_to_postgres scheduled__2024-02-03T04:00:00+00:00 [queued]>
[2024-02-03T05:00:07.304+0000] {taskinstance.py:2171} INFO - Starting attempt 1 of 1
[2024-02-03T05:00:07.323+0000] {taskinstance.py:2192} INFO - Executing <Task(PythonOperator): load_data_to_postgres> on 2024-02-03 04:00:00+00:00
[2024-02-03T05:00:07.331+0000] {standard_task_runner.py:60} INFO - Started process 10566 to run task
[2024-02-03T05:00:07.338+0000] {standard_task_runner.py:87} INFO - Running: ['***', 'tasks', 'run', 'weather_api_dag', 'load_data_to_postgres', 'scheduled__2024-02-03T04:00:00+00:00', '--job-id', '193', '--raw', '--subdir', 'DAGS_FOLDER/weather_api__dag.py', '--cfg-path', '/tmp/tmpvl3chei6']
[2024-02-03T05:00:07.340+0000] {standard_task_runner.py:88} INFO - Job 193: Subtask load_data_to_postgres
[2024-02-03T05:00:07.383+0000] {task_command.py:423} INFO - Running <TaskInstance: weather_api_dag.load_data_to_postgres scheduled__2024-02-03T04:00:00+00:00 [running]> on host 324edfad8c3f
[2024-02-03T05:00:07.460+0000] {taskinstance.py:2481} INFO - Exporting env vars: AIRFLOW_CTX_DAG_OWNER='***' AIRFLOW_CTX_DAG_ID='weather_api_dag' AIRFLOW_CTX_TASK_ID='load_data_to_postgres' AIRFLOW_CTX_EXECUTION_DATE='2024-02-03T04:00:00+00:00' AIRFLOW_CTX_TRY_NUMBER='1' AIRFLOW_CTX_DAG_RUN_ID='scheduled__2024-02-03T04:00:00+00:00'
[2024-02-03T05:00:07.461+0000] {taskinstance.py:2699} ERROR - Task failed with exception
Traceback (most recent call last):
  File "/home/airflow/.local/lib/python3.8/site-packages/airflow/models/taskinstance.py", line 433, in _execute_task
    result = execute_callable(context=context, **execute_callable_kwargs)
  File "/home/airflow/.local/lib/python3.8/site-packages/airflow/operators/python.py", line 199, in execute
    return_value = self.execute_callable()
  File "/home/airflow/.local/lib/python3.8/site-packages/airflow/operators/python.py", line 216, in execute_callable
    return self.python_callable(*self.op_args, **self.op_kwargs)
  File "/opt/airflow/dags/weather_api__dag.py", line 36, in _load_data_to_postgres
    timestamp = context["execution_date"]
NameError: name 'context' is not defined
[2024-02-03T05:00:07.468+0000] {taskinstance.py:1138} INFO - Marking task as FAILED. dag_id=weather_api_dag, task_id=load_data_to_postgres, execution_date=20240203T040000, start_date=20240203T050007, end_date=20240203T050007
[2024-02-03T05:00:07.481+0000] {standard_task_runner.py:107} ERROR - Failed to execute job 193 for task load_data_to_postgres (name 'context' is not defined; 10566)
[2024-02-03T05:00:07.506+0000] {local_task_job_runner.py:234} INFO - Task exited with return code 1
[2024-02-03T05:00:07.525+0000] {taskinstance.py:3281} INFO - 0 downstream tasks scheduled from follow-on schedule check
