[2024-03-09T02:49:34.128+0000] {taskinstance.py:1957} INFO - Dependencies all met for dep_context=non-requeueable deps ti=<TaskInstance: weather_api_dag.load_data_to_postgres manual__2024-03-09T02:49:14.410332+00:00 [queued]>
[2024-03-09T02:49:34.137+0000] {taskinstance.py:1957} INFO - Dependencies all met for dep_context=requeueable deps ti=<TaskInstance: weather_api_dag.load_data_to_postgres manual__2024-03-09T02:49:14.410332+00:00 [queued]>
[2024-03-09T02:49:34.137+0000] {taskinstance.py:2171} INFO - Starting attempt 1 of 1
[2024-03-09T02:49:34.156+0000] {taskinstance.py:2192} INFO - Executing <Task(PythonOperator): load_data_to_postgres> on 2024-03-09 02:49:14.410332+00:00
[2024-03-09T02:49:34.171+0000] {standard_task_runner.py:60} INFO - Started process 2233 to run task
[2024-03-09T02:49:34.178+0000] {standard_task_runner.py:87} INFO - Running: ['***', 'tasks', 'run', 'weather_api_dag', 'load_data_to_postgres', 'manual__2024-03-09T02:49:14.410332+00:00', '--job-id', '453', '--raw', '--subdir', 'DAGS_FOLDER/weather_api__dag.py', '--cfg-path', '/tmp/tmptwluduq_']
[2024-03-09T02:49:34.179+0000] {standard_task_runner.py:88} INFO - Job 453: Subtask load_data_to_postgres
[2024-03-09T02:49:34.234+0000] {task_command.py:423} INFO - Running <TaskInstance: weather_api_dag.load_data_to_postgres manual__2024-03-09T02:49:14.410332+00:00 [running]> on host 70ec329f3d65
[2024-03-09T02:49:34.324+0000] {taskinstance.py:2481} INFO - Exporting env vars: AIRFLOW_CTX_DAG_EMAIL='kan@odds.team' AIRFLOW_CTX_DAG_OWNER='***' AIRFLOW_CTX_DAG_ID='weather_api_dag' AIRFLOW_CTX_TASK_ID='load_data_to_postgres' AIRFLOW_CTX_EXECUTION_DATE='2024-03-09T02:49:14.410332+00:00' AIRFLOW_CTX_TRY_NUMBER='1' AIRFLOW_CTX_DAG_RUN_ID='manual__2024-03-09T02:49:14.410332+00:00'
[2024-03-09T02:49:34.334+0000] {logging_mixin.py:188} INFO - /opt/***/dags/weather_data_2024-03-09T02:49:14.410332+00:00.json
[2024-03-09T02:49:34.335+0000] {warnings.py:109} WARNING - /opt/***/dags/weather_api__dag.py:88: AirflowProviderDeprecationWarning: The "schema" arg has been renamed to "database" as it contained the database name.Please use "database" to set the database name.
  pg_hook = PostgresHook(

[2024-03-09T02:49:34.343+0000] {base.py:83} INFO - Using connection ID 'my_***_conn' for task execution.
[2024-03-09T02:49:34.363+0000] {taskinstance.py:2699} ERROR - Task failed with exception
Traceback (most recent call last):
  File "/home/airflow/.local/lib/python3.8/site-packages/airflow/models/taskinstance.py", line 433, in _execute_task
    result = execute_callable(context=context, **execute_callable_kwargs)
  File "/home/airflow/.local/lib/python3.8/site-packages/airflow/operators/python.py", line 199, in execute
    return_value = self.execute_callable()
  File "/home/airflow/.local/lib/python3.8/site-packages/airflow/operators/python.py", line 216, in execute_callable
    return self.python_callable(*self.op_args, **self.op_kwargs)
  File "/opt/airflow/dags/weather_api__dag.py", line 103, in _load_data_to_postgres
    cursor.execute(sql)
psycopg2.errors.UndefinedColumn: column "dt" of relation "weathers" does not exist
LINE 2:         INSERT INTO weathers (dt, temp) VALUES (1709952310, ...
                                      ^

[2024-03-09T02:49:34.371+0000] {taskinstance.py:1138} INFO - Marking task as FAILED. dag_id=weather_api_dag, task_id=load_data_to_***, execution_date=20240309T024914, start_date=20240309T024934, end_date=20240309T024934
[2024-03-09T02:49:34.381+0000] {warnings.py:109} WARNING - /home/***/.local/lib/python3.8/site-packages/***/utils/email.py:154: RemovedInAirflow3Warning: Fetching SMTP credentials from configuration variables will be deprecated in a future release. Please set credentials using a connection instead.
  send_mime_email(e_from=mail_from, e_to=recipients, mime_msg=msg, conn_id=conn_id, dryrun=dryrun)

[2024-03-09T02:49:34.382+0000] {configuration.py:1046} WARNING - section/key [smtp/smtp_user] not found in config
[2024-03-09T02:49:34.382+0000] {email.py:270} INFO - Email alerting: attempt 1
[2024-03-09T02:49:34.384+0000] {email.py:281} INFO - Sent an alert email to ['kan@odds.team']
[2024-03-09T02:49:34.415+0000] {standard_task_runner.py:107} ERROR - Failed to execute job 453 for task load_data_to_*** (column "dt" of relation "weathers" does not exist
LINE 2:         INSERT INTO weathers (dt, temp) VALUES (1709952310, ...
                                      ^
; 2233)
[2024-03-09T02:49:34.468+0000] {local_task_job_runner.py:234} INFO - Task exited with return code 1
[2024-03-09T02:49:34.488+0000] {taskinstance.py:3281} INFO - 0 downstream tasks scheduled from follow-on schedule check
