[2024-03-09T02:25:16.308+0000] {taskinstance.py:1957} INFO - Dependencies all met for dep_context=non-requeueable deps ti=<TaskInstance: play_with_airflow_connections_and_hooks.get_data scheduled__2024-03-06T00:00:00+00:00 [queued]>
[2024-03-09T02:25:16.319+0000] {taskinstance.py:1957} INFO - Dependencies all met for dep_context=requeueable deps ti=<TaskInstance: play_with_airflow_connections_and_hooks.get_data scheduled__2024-03-06T00:00:00+00:00 [queued]>
[2024-03-09T02:25:16.320+0000] {taskinstance.py:2171} INFO - Starting attempt 1 of 1
[2024-03-09T02:25:16.354+0000] {taskinstance.py:2192} INFO - Executing <Task(PythonOperator): get_data> on 2024-03-06 00:00:00+00:00
[2024-03-09T02:25:16.370+0000] {standard_task_runner.py:60} INFO - Started process 193 to run task
[2024-03-09T02:25:16.404+0000] {standard_task_runner.py:87} INFO - Running: ['***', 'tasks', 'run', 'play_with_***_connections_and_hooks', 'get_data', 'scheduled__2024-03-06T00:00:00+00:00', '--job-id', '439', '--raw', '--subdir', 'DAGS_FOLDER/play_with_***_connections_and_hooks.py', '--cfg-path', '/tmp/tmpi0d1xwmu']
[2024-03-09T02:25:16.412+0000] {standard_task_runner.py:88} INFO - Job 439: Subtask get_data
[2024-03-09T02:25:16.528+0000] {task_command.py:423} INFO - Running <TaskInstance: play_with_airflow_connections_and_hooks.get_data scheduled__2024-03-06T00:00:00+00:00 [running]> on host f31aad17870c
[2024-03-09T02:25:16.765+0000] {taskinstance.py:2481} INFO - Exporting env vars: AIRFLOW_CTX_DAG_OWNER='***' AIRFLOW_CTX_DAG_ID='play_with_***_connections_and_hooks' AIRFLOW_CTX_TASK_ID='get_data' AIRFLOW_CTX_EXECUTION_DATE='2024-03-06T00:00:00+00:00' AIRFLOW_CTX_TRY_NUMBER='1' AIRFLOW_CTX_DAG_RUN_ID='scheduled__2024-03-06T00:00:00+00:00'
[2024-03-09T02:25:16.792+0000] {base.py:83} INFO - Using connection ID 'my_***_conn' for task execution.
[2024-03-09T02:25:16.801+0000] {taskinstance.py:2699} ERROR - Task failed with exception
Traceback (most recent call last):
  File "/home/airflow/.local/lib/python3.8/site-packages/airflow/models/taskinstance.py", line 433, in _execute_task
    result = execute_callable(context=context, **execute_callable_kwargs)
  File "/home/airflow/.local/lib/python3.8/site-packages/airflow/operators/python.py", line 199, in execute
    return_value = self.execute_callable()
  File "/home/airflow/.local/lib/python3.8/site-packages/airflow/operators/python.py", line 216, in execute_callable
    return self.python_callable(*self.op_args, **self.op_kwargs)
  File "/opt/airflow/dags/play_with_airflow_connections_and_hooks.py", line 12, in _get_data
    connection = pg_hook.get_conn()
  File "/home/airflow/.local/lib/python3.8/site-packages/airflow/providers/postgres/hooks/postgres.py", line 158, in get_conn
    self.conn = psycopg2.connect(**conn_args)
  File "/home/airflow/.local/lib/python3.8/site-packages/psycopg2/__init__.py", line 122, in connect
    conn = _connect(dsn, connection_factory=connection_factory, **kwasync)
psycopg2.OperationalError: could not translate host name "mydb" to address: Name or service not known

[2024-03-09T02:25:16.852+0000] {taskinstance.py:1138} INFO - Marking task as FAILED. dag_id=play_with_***_connections_and_hooks, task_id=get_data, execution_date=20240306T000000, start_date=20240309T022516, end_date=20240309T022516
[2024-03-09T02:25:16.902+0000] {standard_task_runner.py:107} ERROR - Failed to execute job 439 for task get_data (could not translate host name "mydb" to address: Name or service not known
; 193)
[2024-03-09T02:25:16.937+0000] {local_task_job_runner.py:234} INFO - Task exited with return code 1
[2024-03-09T02:25:16.991+0000] {taskinstance.py:3281} INFO - 0 downstream tasks scheduled from follow-on schedule check
